<?xml version="1.0" encoding="utf-8"?>
<robot name="warm" xmlns:xacro="http://ros.org/wiki/xacro">
  <xacro:include filename="$(find warm_3kg_description)/urdf/warm.transmission.xacro" />
  <xacro:include filename="$(find warm_3kg_description)/urdf/warm.gazebo.xacro" />
  <xacro:macro name="warm_robot" params="prefix joint_limited
    shoulder_pan_lower_limit:=${-pi}    shoulder_pan_upper_limit:=${pi}
    shoulder_lift_lower_limit:=${-pi}    shoulder_lift_upper_limit:=${pi}
    elbow_joint_lower_limit:=${-pi}    elbow_joint_upper_limit:=${pi}
    wrist_1_lower_limit:=${-pi}    wrist_1_upper_limit:=${pi}
    wrist_2_lower_limit:=${-pi}    wrist_2_upper_limit:=${pi}
    wrist_3_lower_limit:=${-pi}    wrist_3_upper_limit:=${pi}
    transmission_hw_interface:=hardware_interface/PositionJointInterface
    safety_limits:=false safety_pos_margin:=0.15
    safety_k_position:=20">
  
    <link name="${prefix}base_link">
      <inertial>
        <origin
          xyz="0.00023586 -0.00054882 0.01750154"
          rpy="0 0 0" />
        <mass
          value="0.35532746" />
        <inertia
          ixx="0.00038903"
          ixy="0.00000005"
          ixz="0.00000020"
          iyy="0.00037664"
          iyz="-0.00000107"
          izz="0.00060453" />
      </inertial>
      <visual>
        <origin
          xyz="0 0 0"
          rpy="0 0 0" />
        <geometry>
          <mesh
            filename="package://warm_3kg_description/meshes/base_link.STL" />
        </geometry>
        <material
          name="">
          <color
            rgba="0    0.4470    0.7410 1" />
        </material>
      </visual>
      <collision>
        <origin
          xyz="0 0 0"
          rpy="0 0 0" />
        <geometry>
          <mesh
            filename="package://warm_3kg_description/meshes/base_link.STL" />
        </geometry>
      </collision>
    </link>
    <link name="${prefix}shoulder_link">
      <inertial>
        <origin
          xyz="0.00003123 -0.00383907 -0.01097248"
          rpy="0 0 0" />
        <mass
          value="1.71244732" />
        <inertia
          ixx="0.00226039"
          ixy="0.00000110"
          ixz="0.00000183"
          iyy="0.00226232"
          iyz="0.00000136"
          izz="0.00189672" />
      </inertial>
      <visual>
        <origin
          xyz="0 0 0"
          rpy="0 0 0" />
        <geometry>
          <mesh
            filename="package://warm_3kg_description/meshes/shoulder_link.STL" />
        </geometry>
        <material
          name="">
          <color
            rgba="0.8500    0.3250    0.0980 1" />
        </material>
      </visual>
      <collision>
        <origin
          xyz="0 0 0"
          rpy="0 0 0" />
        <geometry>
          <mesh
            filename="package://warm_3kg_description/meshes/shoulder_link.STL" />
        </geometry>
      </collision>
    </link>
    <joint name="${prefix}shoulder_pan_joint"
      type="revolute">
      <origin
        xyz="0 0 0.101"
        rpy="0 0 0" />
      <parent
        link="${prefix}base_link" />
      <child
        link="${prefix}shoulder_link" />
      <axis
        xyz="0 0 1" />
      <xacro:unless value="${joint_limited}">
          <limit lower="${-2.0 * pi}" upper="${2.0 * pi}" effort="150.0" velocity="2.16"/>
          <xacro:if value="${safety_limits}">
            <safety_controller soft_lower_limit="${-2.0 * pi + safety_pos_margin}" soft_upper_limit="${2.0 * pi - safety_pos_margin}" k_position="${safety_k_position}" k_velocity="0.0"/>
          </xacro:if>
        </xacro:unless>
        <xacro:if value="${joint_limited}">
          <limit lower="${shoulder_pan_lower_limit}" upper="${shoulder_pan_upper_limit}" effort="143.0" velocity="1.0"/>
          <xacro:if value="${safety_limits}">
            <safety_controller soft_lower_limit="${shoulder_pan_lower_limit + safety_pos_margin}" soft_upper_limit="${shoulder_pan_upper_limit - safety_pos_margin}" k_position="${safety_k_position}" k_velocity="0.0"/>
          </xacro:if>
        </xacro:if>
        <dynamics damping="0.0" friction="0.0"/>
    </joint>
    <link name="${prefix}upper_arm_link">
      <inertial>
        <origin
          xyz="-0.12149941 -0.00002909 -0.01512573"
          rpy="0 0 0" />
        <mass
          value="3.58532690" />
        <inertia
          ixx="0.00423671"
          ixy="0.00000023"
          ixz="-0.00000006"
          iyy="0.05203041"
          iyz="-0.00000374"
          izz="0.05115322" />
      </inertial>
      <visual>
        <origin
          xyz="0 0 0"
          rpy="0 0 0" />
        <geometry>
          <mesh
            filename="package://warm_3kg_description/meshes/upper_arm_link.STL" />
        </geometry>
        <material
          name="">
          <color
            rgba="0.9290    0.6940    0.1250 1" />
        </material>
      </visual>
      <collision>
        <origin
          xyz="0 0 0"
          rpy="0 0 0" />
        <geometry>
          <mesh
            filename="package://warm_3kg_description/meshes/upper_arm_link.STL" />
        </geometry>
      </collision>
    </link>
    <joint name="${prefix}shoulder_lift_joint"
      type="revolute">
      <origin
        xyz="0 -0.123 0"
        rpy="1.570796326794897 1.570796326794897 0" />
      <parent
        link="${prefix}shoulder_link" />
      <child
        link="${prefix}upper_arm_link" />
      <axis
        xyz="0 0 1" />
      <xacro:unless value="${joint_limited}">
          <limit lower="${-2.0 * pi}" upper="${2.0 * pi}" effort="150.0" velocity="2.16"/>
          <xacro:if value="${safety_limits}">
            <safety_controller soft_lower_limit="${-2.0 * pi + safety_pos_margin}" soft_upper_limit="${2.0 * pi - safety_pos_margin}" k_position="${safety_k_position}" k_velocity="0.0"/>
          </xacro:if>
        </xacro:unless>
        <xacro:if value="${joint_limited}">
          <limit lower="${shoulder_lift_lower_limit}" upper="${shoulder_lift_upper_limit}" effort="143.0" velocity="1.0"/>
          <xacro:if value="${safety_limits}">
            <safety_controller soft_lower_limit="${shoulder_lift_lower_limit + safety_pos_margin}" soft_upper_limit="${shoulder_lift_upper_limit - safety_pos_margin}" k_position="${safety_k_position}" k_velocity="0.0"/>
          </xacro:if>
        </xacro:if>
        <dynamics damping="0.0" friction="0.0"/>
    </joint>
    <link name="${prefix}forearm_link">
      <inertial>
        <origin
          xyz="-0.16246906 0.00002670 0.01287077"
          rpy="0 0 0" />
        <mass
          value="1.74820976" />
        <inertia
          ixx="0.00193679"
          ixy="-0.00000193"
          ixz="-0.00037201"
          iyy="0.01409296"
          iyz="-0.00000133"
          izz="0.01376533" />
      </inertial>
      <visual>
        <origin
          xyz="0 0 0"
          rpy="0 0 0" />
        <geometry>
          <mesh
            filename="package://warm_3kg_description/meshes/forearm_link.STL" />
        </geometry>
        <material
          name="">
          <color
            rgba="0.4940    0.1840    0.5560 1" />
        </material>
      </visual>
      <collision>
        <origin
          xyz="0 0 0"
          rpy="0 0 0" />
        <geometry>
          <mesh
            filename="package://warm_3kg_description/meshes/forearm_link.STL" />
        </geometry>
      </collision>
    </link>
    <joint name="${prefix}elbow_joint"
      type="revolute">
      <origin
        xyz="-0.243 0 -0.113"
        rpy="0 0 0" />
      <parent
        link="${prefix}upper_arm_link" />
      <child
        link="${prefix}forearm_link" />
      <axis
        xyz="0 0 1" />
      <xacro:unless value="${joint_limited}">
          <limit lower="${-pi}" upper="${pi}" effort="150.0" velocity="3.14"/>
          <xacro:if value="${safety_limits}">
            <safety_controller soft_lower_limit="${-2.0 * pi + safety_pos_margin}" soft_upper_limit="${2.0 * pi - safety_pos_margin}" k_position="${safety_k_position}" k_velocity="0.0"/>
          </xacro:if>
        </xacro:unless>
        <xacro:if value="${joint_limited}">
          <limit lower="${elbow_joint_lower_limit}" upper="${elbow_joint_upper_limit}" effort="143.0" velocity="1.0"/>
          <xacro:if value="${safety_limits}">
            <safety_controller soft_lower_limit="${elbow_joint_lower_limit + safety_pos_margin}" soft_upper_limit="${elbow_joint_upper_limit - safety_pos_margin}" k_position="${safety_k_position}" k_velocity="0.0"/>
          </xacro:if>
        </xacro:if>
        <dynamics damping="0.0" friction="0.0"/>
    </joint>
    <link name="${prefix}wrist_1_link">
      <inertial>
        <origin
          xyz="-0.00003635 -0.01183476 -0.00325078"
          rpy="0 0 0" />
        <mass
          value="1.28778952" />
        <inertia
          ixx="0.00140382"
          ixy="-0.00000142"
          ixz="-0.00000067"
          iyy="0.00119914"
          iyz="-0.00004837"
          izz="0.00128720" />
      </inertial>
      <visual>
        <origin
          xyz="0 0 0"
          rpy="0 0 0" />
        <geometry>
          <mesh
            filename="package://warm_3kg_description/meshes/wrist_1_link.STL" />
        </geometry>
        <material
          name="">
          <color
            rgba="0.4660    0.6740    0.1880 1" />
        </material>
      </visual>
      <collision>
        <origin
          xyz="0 0 0"
          rpy="0 0 0" />
        <geometry>
          <mesh
            filename="package://warm_3kg_description/meshes/wrist_1_link.STL" />
        </geometry>
      </collision>
    </link>
    <joint name="${prefix}wrist_1_joint"
      type="revolute">
      <origin
        xyz="-0.214 0 0.113"
        rpy="0 0 -1.570796326794897" />
      <parent
        link="${prefix}forearm_link" />
      <child
        link="${prefix}wrist_1_link" />
      <axis
        xyz="0 0 1" />
      <xacro:unless value="${joint_limited}">
          <limit lower="${-2.0 * pi}" upper="${2.0 * pi}" effort="54.0" velocity="3.14"/>
          <xacro:if value="${safety_limits}">
            <safety_controller soft_lower_limit="${-2.0 * pi + safety_pos_margin}" soft_upper_limit="${2.0 * pi - safety_pos_margin}" k_position="${safety_k_position}" k_velocity="0.0"/>
          </xacro:if>
        </xacro:unless>
        <xacro:if value="${joint_limited}">
          <limit lower="${wrist_1_lower_limit}" upper="${wrist_1_upper_limit}" effort="70.0" velocity="1.0"/>
          <xacro:if value="${safety_limits}">
            <safety_controller soft_lower_limit="${wrist_1_lower_limit + safety_pos_margin}" soft_upper_limit="${wrist_1_upper_limit - safety_pos_margin}" k_position="${safety_k_position}" k_velocity="0.0"/>
          </xacro:if>
        </xacro:if>
        <dynamics damping="0.0" friction="0.0"/>
    </joint>
    <link name="${prefix}wrist_2_link">
      <inertial>
        <origin
          xyz="0.00005222 0.01183476 -0.00333943"
          rpy="0 0 0" />
        <mass
          value="1.28778952" />
        <inertia
          ixx="0.00140353"
          ixy="-0.00000186"
          ixz="-0.00000029"
          iyy="0.00119838"
          iyz="0.00005166"
          izz="0.00128674" />
      </inertial>
      <visual>
        <origin
          xyz="0 0 0"
          rpy="0 0 0" />
        <geometry>
          <mesh
            filename="package://warm_3kg_description/meshes/wrist_2_link.STL" />
        </geometry>
        <material
          name="">
          <color
            rgba="0.3010    0.7450    0.9330 1" />
        </material>
      </visual>
      <collision>
        <origin
          xyz="0 0 0"
          rpy="0 0 0" />
        <geometry>
          <mesh
            filename="package://warm_3kg_description/meshes/wrist_2_link.STL" />
        </geometry>
      </collision>
    </link>
    <joint name="${prefix}wrist_2_joint"
      type="revolute">
      <origin
        xyz="0 -0.11 0"
        rpy="1.570796326794897 0 0" />
      <parent
        link="${prefix}wrist_1_link" />
      <child
        link="${prefix}wrist_2_link" />
      <axis
        xyz="0 0 1" />
      <xacro:unless value="${joint_limited}">
          <limit lower="${-2.0 * pi}" upper="${2.0 * pi}" effort="54.0" velocity="3.14"/>
          <xacro:if value="${safety_limits}">
            <safety_controller soft_lower_limit="${-2.0 * pi + safety_pos_margin}" soft_upper_limit="${2.0 * pi - safety_pos_margin}" k_position="${safety_k_position}" k_velocity="0.0"/>
          </xacro:if>
        </xacro:unless>
        <xacro:if value="${joint_limited}">
          <limit lower="${wrist_2_lower_limit}" upper="${wrist_2_upper_limit}" effort="70.0" velocity="1.0"/>
          <xacro:if value="${safety_limits}">
            <safety_controller soft_lower_limit="${wrist_2_lower_limit + safety_pos_margin}" soft_upper_limit="${wrist_2_upper_limit - safety_pos_margin}" k_position="${safety_k_position}" k_velocity="0.0"/>
          </xacro:if>
        </xacro:if>
        <dynamics damping="0.0" friction="0.0"/>
    </joint>
    <link name="${prefix}wrist_3_link">
      <inertial>
        <origin
          xyz="0.00000000 0.00000782 -0.01004152"
          rpy="0 0 0" />
        <mass
          value="0.11579920" />
        <inertia
          ixx="0.00003453"
          ixy="0.00000000"
          ixz="0.00000000"
          iyy="0.00003456"
          iyz="0.00000000"
          izz="0.00006000" />
      </inertial>
      <visual>
        <origin
          xyz="0 0 0"
          rpy="0 0 0" />
        <geometry>
          <mesh
            filename="package://warm_3kg_description/meshes/wrist_3_link.STL" />
        </geometry>
        <material
          name="">
          <color
            rgba="0.6350    0.0780    0.1840 1" />
        </material>
      </visual>
      <collision>
        <origin
          xyz="0 0 0"
          rpy="0 0 0" />
        <geometry>
          <mesh
            filename="package://warm_3kg_description/meshes/wrist_3_link.STL" />
        </geometry>
      </collision>
    </link>
    <joint name="${prefix}wrist_3_joint"
      type="revolute">
      <origin
        xyz="0 0.07525 0"
        rpy="-1.570796326794897 0 0" />
      <parent
        link="${prefix}wrist_2_link" />
      <child
        link="${prefix}wrist_3_link" />
      <axis
        xyz="0 0 1" />
      <xacro:unless value="${joint_limited}">
          <limit lower="${-2.0 * pi}" upper="${2.0 * pi}" effort="54.0" velocity="3.14"/>
          <xacro:if value="${safety_limits}">
            <safety_controller soft_lower_limit="${-2.0 * pi + safety_pos_margin}" soft_upper_limit="${2.0 * pi - safety_pos_margin}" k_position="${safety_k_position}" k_velocity="0.0"/>
          </xacro:if>
        </xacro:unless>
        <xacro:if value="${joint_limited}">
          <limit lower="${wrist_3_lower_limit}" upper="${wrist_3_upper_limit}" effort="70.0" velocity="1.0"/>
          <xacro:if value="${safety_limits}">
            <safety_controller soft_lower_limit="${wrist_3_lower_limit + safety_pos_margin}" soft_upper_limit="${wrist_3_upper_limit - safety_pos_margin}" k_position="${safety_k_position}" k_velocity="0.0"/>
          </xacro:if>
        </xacro:if>
        <dynamics damping="0.0" friction="0.0"/>
    </joint>
    
    <xacro:warm_transmission prefix="${prefix}" />
    <xacro:warm_gazebo prefix="${prefix}" />

    <link name="${prefix}base"/>
    <joint name="${prefix}base_link-base_fixed_joint" type="fixed">
      <origin xyz="0 0 0" rpy="0 0 ${-pi}"/>
      <parent link="${prefix}base_link"/>
      <child link="${prefix}base"/>
    </joint>

  </xacro:macro>
</robot>