#VRML_SIM R2022b utf8
# license: Apache License 2.0
# license url: http://www.apache.org/licenses/LICENSE-2.0
# This is a proto file for Webots for the Warm3kgDescription
# Extracted from: C:\Users\Neil\warm_3kg_description\urdf\warm_3kg_description_xiugai.urdf

PROTO Warm3kgDescription [
  field  SFVec3f     translation     0 0 0
  field  SFRotation  rotation        0 0 1 0
  field  SFString    name            "Warm3kgDescription"  # Is `Robot.name`.
  field  SFString    controller      "void"                # Is `Robot.controller`.
  field  MFString    controllerArgs  []                    # Is `Robot.controllerArgs`.
  field  SFString    customData      ""                    # Is `Robot.customData`.
  field  SFBool      supervisor      FALSE                 # Is `Robot.supervisor`.
  field  SFBool      synchronization TRUE                  # Is `Robot.synchronization`.
  field  SFBool      selfCollision   FALSE                 # Is `Robot.selfCollision`.
]
{
  Robot {
    translation IS translation
    rotation IS rotation
    controller IS controller
    controllerArgs IS controllerArgs
    customData IS customData
    supervisor IS supervisor
    synchronization IS synchronization
    selfCollision IS selfCollision
    children [
      Shape {
        appearance DEF base_link_material PBRAppearance {
          baseColor 0.000000 0.447000 0.741000
          roughness 1.000000
          metalness 0
        }
        geometry DEF base_link Mesh {
          url "C:\Users\Neil/warm_3kg_description/meshes/base_link.STL"
        }
      }
      HingeJoint {
        jointParameters HingeJointParameters {
          axis 0.000000 0.000000 1.000000
          anchor 0.000000 0.000000 0.101000
        }
        device [
          RotationalMotor {
            name "shoulder_pan_joint"
            maxVelocity 2.16
            minPosition -3.141592653589793
            maxPosition 3.141592653589793
            maxTorque 150.0
          }
          PositionSensor {
            name "shoulder_pan_joint_sensor"
          }
        ]
        endPoint Solid {
          translation 0.000000 0.000000 0.101000
          children [
            Shape {
              appearance DEF shoulder_link_material PBRAppearance {
                baseColor 0.850000 0.325000 0.098000
                roughness 1.000000
                metalness 0
              }
              geometry DEF shoulder_link Mesh {
                url "C:\Users\Neil/warm_3kg_description/meshes/shoulder_link.STL"
              }
            }
            HingeJoint {
              jointParameters HingeJointParameters {
                axis -0.000000 -1.000000 0.000000
                anchor 0.000000 -0.123000 0.000000
              }
              device [
                RotationalMotor {
                  name "shoulder_lift_joint"
                  maxVelocity 2.16
                  minPosition -2.5482
                  maxPosition 2.5482
                  maxTorque 150.0
                }
                PositionSensor {
                  name "shoulder_lift_joint_sensor"
                }
              ]
              endPoint Solid {
                translation 0.000000 -0.123000 0.000000
                rotation 0.577350 0.577350 -0.577350 2.094395
                children [
                  Shape {
                    appearance DEF upper_arm_link_material PBRAppearance {
                      baseColor 0.929000 0.694000 0.125000
                      roughness 1.000000
                      metalness 0
                    }
                    geometry DEF upper_arm_link Mesh {
                      url "C:\Users\Neil/warm_3kg_description/meshes/upper_arm_link.STL"
                    }
                  }
                  HingeJoint {
                    jointParameters HingeJointParameters {
                      axis 0.000000 0.000000 1.000000
                      anchor -0.243000 0.000000 -0.113000
                    }
                    device [
                      RotationalMotor {
                        name "elbow_joint"
                        maxVelocity 3.15
                        minPosition -2.5482
                        maxPosition 2.5482
                        maxTorque 150.0
                      }
                      PositionSensor {
                        name "elbow_joint_sensor"
                      }
                    ]
                    endPoint Solid {
                      translation -0.243000 0.000000 -0.113000
                      children [
                        Shape {
                          appearance DEF forearm_link_material PBRAppearance {
                            baseColor 0.494000 0.184000 0.556000
                            roughness 1.000000
                            metalness 0
                          }
                          geometry DEF forearm_link Mesh {
                            url "C:\Users\Neil/warm_3kg_description/meshes/forearm_link.STL"
                          }
                        }
                        HingeJoint {
                          jointParameters HingeJointParameters {
                            axis 0.000000 -0.000000 1.000000
                            anchor -0.214000 0.000000 0.113000
                          }
                          device [
                            RotationalMotor {
                              name "wrist_1_joint"
                              maxVelocity 3.2
                              minPosition -3.141592653589793
                              maxPosition 3.141592653589793
                              maxTorque 54.0
                            }
                            PositionSensor {
                              name "wrist_1_joint_sensor"
                            }
                          ]
                          endPoint Solid {
                            translation -0.214000 0.000000 0.113000
                            rotation 0.000000 0.000000 -1.000000 1.570796
                            children [
                              Shape {
                                appearance DEF wrist_1_link_material PBRAppearance {
                                  baseColor 0.466000 0.674000 0.188000
                                  roughness 1.000000
                                  metalness 0
                                }
                                geometry DEF wrist_1_link Mesh {
                                  url "C:\Users\Neil/warm_3kg_description/meshes/wrist_1_link.STL"
                                }
                              }
                              HingeJoint {
                                jointParameters HingeJointParameters {
                                  axis 0.000000 -1.000000 -0.000000
                                  anchor 0.000000 -0.110000 0.000000
                                }
                                device [
                                  RotationalMotor {
                                    name "wrist_2_joint"
                                    maxVelocity 3.2
                                    minPosition -3.141592653589793
                                    maxPosition 3.141592653589793
                                    maxTorque 54.0
                                  }
                                  PositionSensor {
                                    name "wrist_2_joint_sensor"
                                  }
                                ]
                                endPoint Solid {
                                  translation 0.000000 -0.110000 0.000000
                                  rotation 1.000000 0.000000 0.000000 1.570796
                                  children [
                                    Shape {
                                      appearance DEF wrist_2_link_material PBRAppearance {
                                        baseColor 0.301000 0.745000 0.933000
                                        roughness 1.000000
                                        metalness 0
                                      }
                                      geometry DEF wrist_2_link Mesh {
                                        url "C:\Users\Neil/warm_3kg_description/meshes/wrist_2_link.STL"
                                      }
                                    }
                                    HingeJoint {
                                      jointParameters HingeJointParameters {
                                        axis 0.000000 1.000000 -0.000000
                                        anchor 0.000000 0.075250 0.000000
                                      }
                                      device [
                                        RotationalMotor {
                                          name "wrist_3_joint"
                                          maxVelocity 3.2
                                          minPosition -3.141592653589793
                                          maxPosition 3.141592653589793
                                          maxTorque 54.0
                                        }
                                        PositionSensor {
                                          name "wrist_3_joint_sensor"
                                        }
                                      ]
                                      endPoint Solid {
                                        translation 0.000000 0.075250 0.000000
                                        rotation -1.000000 0.000000 0.000000 1.570796
                                        children [
                                          Shape {
                                            appearance DEF wrist_3_link_material PBRAppearance {
                                              baseColor 0.635000 0.078000 0.184000
                                              roughness 1.000000
                                              metalness 0
                                            }
                                            geometry DEF wrist_3_link Mesh {
                                              url "C:\Users\Neil/warm_3kg_description/meshes/wrist_3_link.STL"
                                            }
                                          }
                                        ]
                                        name "wrist_3_link"
                                        boundingObject USE wrist_3_link
                                        physics Physics {
                                          density -1
                                          mass 0.115799
                                          centerOfMass [ 0.000000 0.000008 -0.010042 ]
                                          inertiaMatrix [
                                            3.453000e-05 3.456000e-05 6.000000e-05
                                            0.000000e+00 0.000000e+00 0.000000e+00
                                          ]
                                        }
                                      }
                                    }
                                  ]
                                  name "wrist_2_link"
                                  boundingObject USE wrist_2_link
                                  physics Physics {
                                    density -1
                                    mass 1.287790
                                    centerOfMass [ 0.000052 0.011835 -0.003339 ]
                                    inertiaMatrix [
                                      1.403530e-03 1.198380e-03 1.286740e-03
                                      -1.860000e-06 -2.900000e-07 5.166000e-05
                                    ]
                                  }
                                }
                              }
                            ]
                            name "wrist_1_link"
                            boundingObject USE wrist_1_link
                            physics Physics {
                              density -1
                              mass 1.287790
                              centerOfMass [ -0.000036 -0.011835 -0.003251 ]
                              inertiaMatrix [
                                1.403820e-03 1.199140e-03 1.287200e-03
                                -1.420000e-06 -6.700000e-07 -4.837000e-05
                              ]
                            }
                          }
                        }
                      ]
                      name "forearm_link"
                      boundingObject USE forearm_link
                      physics Physics {
                        density -1
                        mass 1.748210
                        centerOfMass [ -0.162469 0.000027 0.012871 ]
                        inertiaMatrix [
                          1.936790e-03 1.409296e-02 1.376533e-02
                          -1.930000e-06 -3.720100e-04 -1.330000e-06
                        ]
                      }
                    }
                  }
                ]
                name "upper_arm_link"
                boundingObject USE upper_arm_link
                physics Physics {
                  density -1
                  mass 3.585327
                  centerOfMass [ -0.121499 -0.000029 -0.015126 ]
                  inertiaMatrix [
                    4.236710e-03 5.203041e-02 5.115322e-02
                    2.300000e-07 -6.000000e-08 -3.740000e-06
                  ]
                }
              }
            }
          ]
          name "shoulder_link"
          boundingObject USE shoulder_link
          physics Physics {
            density -1
            mass 1.712447
            centerOfMass [ 0.000031 -0.003839 -0.010972 ]
            inertiaMatrix [
              2.260390e-03 2.262320e-03 1.896720e-03
              1.100000e-06 1.830000e-06 1.360000e-06
            ]
          }
        }
      }
    ]
    name IS name
    boundingObject USE base_link
    physics Physics {
      density -1
      mass 0.355327
      centerOfMass [ 0.000236 -0.000549 0.017502 ]
      inertiaMatrix [
        3.890300e-04 3.766400e-04 6.045300e-04
        5.000000e-08 2.000000e-07 -1.070000e-06
      ]
    }
  }
}
